<mujoco>
    <option timestep="0.0002" />
    <actuator>
        <motor gear="1" joint="hinge_1" name="motor_1" ctrlrange="-1 1" ctrllimited="true"/>
        <motor gear="1" joint="hinge_4" name="motor_2" ctrlrange="-1 1" ctrllimited="true"/>
    </actuator>
    <asset>
        <material name="blue" rgba="0 0 1 1" />
        <material name="green" rgba="0 1 0 1" />
        <material name="red" rgba="1 0 0 1" />
        <material name="white" rgba="1 1 1 1" />
    </asset>
    <worldbody>
        <!-- <geom type="plane" size="10 10 0.1" pos="-2 0 0" euler="0 90 0" material="white" /> -->
        <light diffuse=".5 .5 .5" pos="0 0 3" dir="0 0 -1" />
        <body name="link_0" pos="0 -1 0" euler="0 90 0">
            <joint name="hinge_0" axis="0 0 1" />
            <geom type="cylinder" size=".1 .1" material="red" />
            <geom type="box" size=".25 .05 .05" pos="-0.15 0 0" material="white" />
            <inertial pos="0 0 0" mass="0.02" diaginertia="0.01 0.01 0.01"/>
            
            <body name="link_1" pos="-.5 0 0">
                <joint name="hinge_1" axis="0 0 1" />
                <geom type="cylinder" size=".1 .1" material="green" />
                <geom type="box" size=".05 .25 .05" pos="0 .15 0" material="white" />
                <inertial pos="0 0 0" mass="0.02" diaginertia="0.01 0.01 0.01"/>
                
                <body name="link_2" pos="0 .5 0">
                    <joint name="hinge_2" axis="0 0 1" />
                    <geom type="cylinder" size=".1 .1" material="blue" />
                    <geom type="box" size=".05 .25 .05" pos="0 .15 0" material="white" />
                    <inertial pos="0 0 0" mass="0.02" diaginertia="0.01 0.01 0.01"/>
                    
                    <body name="link_3" pos="0 .5 0">
                        <joint name="hinge_3" axis="0 0 1" />
                        <geom type="cylinder" size=".1 .1" material="green" />
                        <geom type="box" size=".25 .05 .05" pos=".15 0 0" material="white" />
                        <inertial pos="0 0 0" mass="0.02" diaginertia="0.01 0.01 0.01"/>
                        
                        <body name="link_4" pos=".5 0 0" euler="0 0 0">
                            <joint name="hinge_4" axis="0 0 1" />
                            <geom type="cylinder" size=".1 .1" material="red" />
                            <inertial pos="0 0 0" mass="0.02" diaginertia="0.01 0.01 0.01"/>
                        </body>
                    </body>
                </body>
            </body>
        </body>
    </worldbody>

    <equality>
        <connect name="kinematic_link" active="true" body1="link_4" anchor="0 0 0" />
    </equality>

    <contact>
       <exclude body1="link_0" body2="link_1"/>
       <exclude body1="link_0" body2="link_3"/>
       <exclude body1="link_0" body2="link_2"/>
       <exclude body1="link_1" body2="link_3"/>
       <exclude body1="link_1" body2="link_2"/>
       <exclude body1="link_2" body2="link_3"/>
   </contact>


</mujoco>