<?xml version="1.0" ?>
<robot name="itp2">
<mujoco>
  <compiler balanceinertia="true" discardvisual="false" meshdir="meshes" fusestatic="false"/>
</mujoco>
<link name="base_link">
  <inertial>
    <origin xyz="-4.28110505425844e-17 9.275727617559952e-17 0.0" rpy="0 0 0"/>
    <mass value="0.31269088172467374"/>
    <inertia ixx="0.0005627556700949108" iyy="0.0005627556700949188" izz="0.001104459216574521" ixy="1.0709300113376218e-18" iyz="-2.2311041902867143e-20" ixz="0.0"/>
  </inertial>
  <visual>
    <origin xyz="0 0 0" rpy="0 0 0"/>
    <geometry>
      <mesh filename="meshes/base_link.stl" scale="0.001 0.001 0.001"/>
    </geometry>
  </visual>
  <collision>
    <origin xyz="0 0 0" rpy="0 0 0"/>
    <geometry>
      <mesh filename="meshes/base_link.stl" scale="0.001 0.001 0.001"/>
    </geometry>
  </collision>
</link>

<link name="l_link_down1">
  <inertial>
    <origin xyz="-0.020733135994442133 -0.02801688872157571 0.028016888721575074" rpy="0 0 0"/>
    <mass value="0.09643048480330162"/>
    <inertia ixx="5.47588545979649e-05" iyy="7.887496262357974e-05" izz="7.887496262357972e-05" ixy="-3.146432362828854e-05" iyz="2.4116108025676374e-05" ixz="3.1464323628288524e-05"/>
  </inertial>
  <visual>
    <origin xyz="-0.060355 0.0 -0.0" rpy="0 0 0"/>
    <geometry>
      <mesh filename="meshes/l_link_down1.stl" scale="0.001 0.001 0.001"/>
    </geometry>

  </visual>
  <collision>
    <origin xyz="-0.060355 0.0 -0.0" rpy="0 0 0"/>
    <geometry>
      <mesh filename="meshes/l_link_down1.stl" scale="0.001 0.001 0.001"/>
    </geometry>
  </collision>
</link>

<link name="l_link_down2">
  <inertial>
    <origin xyz="0.02801688872157509 -0.020733135994442146 0.02801688872157506" rpy="0 0 0"/>
    <mass value="0.09643048480330162"/>
    <inertia ixx="7.887496262357947e-05" iyy="5.475885459796503e-05" izz="7.887496262357947e-05" ixy="3.14643236282885e-05" iyz="3.146432362828855e-05" ixz="-2.411610802567636e-05"/>
  </inertial>
  <visual>
    <origin xyz="-0.0 -0.060355 -0.0" rpy="0 0 0"/>
    <geometry>
      <mesh filename="meshes/l_link_down2.stl" scale="0.001 0.001 0.001"/>
    </geometry>

  </visual>
  <collision>
    <origin xyz="-0.0 -0.060355 -0.0" rpy="0 0 0"/>
    <geometry>
      <mesh filename="meshes/l_link_down2.stl" scale="0.001 0.001 0.001"/>
    </geometry>
  </collision>
</link>

<link name="l_link_down3">
  <inertial>
    <origin xyz="0.020733135994442146 0.028016888721575716 0.028016888721575074" rpy="0 0 0"/>
    <mass value="0.09643048480330162"/>
    <inertia ixx="5.475885459796484e-05" iyy="7.887496262357982e-05" izz="7.887496262357977e-05" ixy="-3.146432362828855e-05" iyz="-2.4116108025676346e-05" ixz="-3.14643236282885e-05"/>
  </inertial>
  <visual>
    <origin xyz="0.060355 -0.0 -0.0" rpy="0 0 0"/>
    <geometry>
      <mesh filename="meshes/l_link_down3.stl" scale="0.001 0.001 0.001"/>
    </geometry>

  </visual>
  <collision>
    <origin xyz="0.060355 -0.0 -0.0" rpy="0 0 0"/>
    <geometry>
      <mesh filename="meshes/l_link_down3.stl" scale="0.001 0.001 0.001"/>
    </geometry>
  </collision>
</link>

<link name="l_link_down4">
  <inertial>
    <origin xyz="-0.028016888721575723 0.020733135994442146 0.028016888721575074" rpy="0 0 0"/>
    <mass value="0.09643048480330162"/>
    <inertia ixx="7.887496262357982e-05" iyy="5.47588545979649e-05" izz="7.887496262357972e-05" ixy="3.146432362828855e-05" iyz="-3.14643236282885e-05" ixz="2.4116108025676346e-05"/>
  </inertial>
  <visual>
    <origin xyz="0.0 0.060355 -0.0" rpy="0 0 0"/>
    <geometry>
      <mesh filename="meshes/l_link_down4.stl" scale="0.001 0.001 0.001"/>
    </geometry>

  </visual>
  <collision>
    <origin xyz="0.0 0.060355 -0.0" rpy="0 0 0"/>
    <geometry>
      <mesh filename="meshes/l_link_down4.stl" scale="0.001 0.001 0.001"/>
    </geometry>
  </collision>
</link>

<link name="v_link1">
  <inertial>
    <origin xyz="0.04915865567859516 7.354447085013556e-15 -0.010754999999999994" rpy="0 0 0"/>
    <mass value="0.028819963707284894"/>
    <inertia ixx="2.8657005996045152e-06" iyy="2.33879319481135e-06" izz="1.4974559265121772e-06" ixy="1.0962483466765328e-19" iyz="0.0" ixz="1.3552527156068805e-20"/>
  </inertial>
  <visual>
    <origin xyz="-0.0 0.0 -0.065755" rpy="0 0 0"/>
    <geometry>
      <mesh filename="meshes/v_link1.stl" scale="0.001 0.001 0.001"/>
    </geometry>

  </visual>
  <collision>
    <origin xyz="-0.0 0.0 -0.065755" rpy="0 0 0"/>
    <geometry>
      <mesh filename="meshes/v_link1.stl" scale="0.001 0.001 0.001"/>
    </geometry>
  </collision>
</link>

<link name="v_link2">
  <inertial>
    <origin xyz="-7.351436985497198e-15 0.04915865567859516 -0.010754999999999994" rpy="0 0 0"/>
    <mass value="0.028819963707284894"/>
    <inertia ixx="2.33879319481135e-06" iyy="2.8657005996045152e-06" izz="1.4974559265121772e-06" ixy="-1.0959257089431901e-19" iyz="1.3552527156068805e-20" ixz="-1.5407439555097887e-33"/>
  </inertial>
  <visual>
    <origin xyz="-0.0 -0.0 -0.065755" rpy="0 0 0"/>
    <geometry>
      <mesh filename="meshes/v_link2.stl" scale="0.001 0.001 0.001"/>
    </geometry>

  </visual>
  <collision>
    <origin xyz="-0.0 -0.0 -0.065755" rpy="0 0 0"/>
    <geometry>
      <mesh filename="meshes/v_link2.stl" scale="0.001 0.001 0.001"/>
    </geometry>
  </collision>
</link>

<link name="v_link3">
  <inertial>
    <origin xyz="-0.04915865567859516 -7.348426885980838e-15 -0.010754999999999994" rpy="0 0 0"/>
    <mass value="0.028819963707284894"/>
    <inertia ixx="2.8657005996045152e-06" iyy="2.33879319481135e-06" izz="1.4974559265121772e-06" ixy="1.0956030712098166e-19" iyz="0.0" ixz="-1.3552527156068805e-20"/>
  </inertial>
  <visual>
    <origin xyz="0.0 -0.0 -0.065755" rpy="0 0 0"/>
    <geometry>
      <mesh filename="meshes/v_link3.stl" scale="0.001 0.001 0.001"/>
    </geometry>

  </visual>
  <collision>
    <origin xyz="0.0 -0.0 -0.065755" rpy="0 0 0"/>
    <geometry>
      <mesh filename="meshes/v_link3.stl" scale="0.001 0.001 0.001"/>
    </geometry>
  </collision>
</link>

<link name="v_link4">
  <inertial>
    <origin xyz="7.345416786464478e-15 -0.04915865567859516 -0.010754999999999994" rpy="0 0 0"/>
    <mass value="0.028819963707284894"/>
    <inertia ixx="2.33879319481135e-06" iyy="2.8657005996045152e-06" izz="1.4974559265121772e-06" ixy="-1.0952804334764277e-19" iyz="-1.3552527156068805e-20" ixz="-1.5407439555097887e-33"/>
  </inertial>
  <visual>
    <origin xyz="-0.0 0.0 -0.065755" rpy="0 0 0"/>
    <geometry>
      <mesh filename="meshes/v_link4.stl" scale="0.001 0.001 0.001"/>
    </geometry>

  </visual>
  <collision>
    <origin xyz="-0.0 0.0 -0.065755" rpy="0 0 0"/>
    <geometry>
      <mesh filename="meshes/v_link4.stl" scale="0.001 0.001 0.001"/>
    </geometry>
  </collision>
</link>

<joint name="Revolute_6" type="continuous">
  <origin xyz="0.060355 0.0 0.0" rpy="0 0 0"/>
  <parent link="base_link"/>
  <child link="l_link_down1"/>
  <axis xyz="-1.0 0.0 0.0"/>
</joint>
<transmission name="Revolute_6_tran">
  <type>transmission_interface/SimpleTransmission</type>
  <joint name="Revolute_6">
    <hardwareInterface>PositionJointInterface</hardwareInterface>
  </joint>
  <actuator name="Revolute_6_actr">
    <hardwareInterface>PositionJointInterface</hardwareInterface>
    <mechanicalReduction>1</mechanicalReduction>
  </actuator>
</transmission>

<joint name="Revolute_7" type="continuous">
  <origin xyz="0.0 0.060355 0.0" rpy="0 0 0"/>
  <parent link="base_link"/>
  <child link="l_link_down2"/>
  <axis xyz="-0.0 -1.0 0.0"/>
</joint>
<transmission name="Revolute_7_tran">
  <type>transmission_interface/SimpleTransmission</type>
  <joint name="Revolute_7">
    <hardwareInterface>PositionJointInterface</hardwareInterface>
  </joint>
  <actuator name="Revolute_7_actr">
    <hardwareInterface>PositionJointInterface</hardwareInterface>
    <mechanicalReduction>1</mechanicalReduction>
  </actuator>
</transmission>

<joint name="Revolute_8" type="continuous">
  <origin xyz="-0.060355 0.0 0.0" rpy="0 0 0"/>
  <parent link="base_link"/>
  <child link="l_link_down3"/>
  <axis xyz="1.0 -0.0 0.0"/>
</joint>
<transmission name="Revolute_8_tran">
  <type>transmission_interface/SimpleTransmission</type>
  <joint name="Revolute_8">
    <hardwareInterface>PositionJointInterface</hardwareInterface>
  </joint>
  <actuator name="Revolute_8_actr">
    <hardwareInterface>PositionJointInterface</hardwareInterface>
    <mechanicalReduction>1</mechanicalReduction>
  </actuator>
</transmission>

<joint name="Revolute_9" type="continuous">
  <origin xyz="0.0 -0.060355 0.0" rpy="0 0 0"/>
  <parent link="base_link"/>
  <child link="l_link_down4"/>
  <axis xyz="0.0 1.0 0.0"/>
</joint>
<transmission name="Revolute_9_tran">
  <type>transmission_interface/SimpleTransmission</type>
  <joint name="Revolute_9">
    <hardwareInterface>PositionJointInterface</hardwareInterface>
  </joint>
  <actuator name="Revolute_9_actr">
    <hardwareInterface>PositionJointInterface</hardwareInterface>
    <mechanicalReduction>1</mechanicalReduction>
  </actuator>
</transmission>

<joint name="Revolute_10" type="continuous">
  <origin xyz="0.0 -0.060355 0.065755" rpy="0 0 0"/>
  <parent link="l_link_down2"/>
  <child link="v_link1"/>
  <axis xyz="-0.707107 0.0 -0.707107"/>
</joint>
<transmission name="Revolute_10_tran">
  <type>transmission_interface/SimpleTransmission</type>
  <joint name="Revolute_10">
    <hardwareInterface>PositionJointInterface</hardwareInterface>
  </joint>
  <actuator name="Revolute_10_actr">
    <hardwareInterface>PositionJointInterface</hardwareInterface>
    <mechanicalReduction>1</mechanicalReduction>
  </actuator>
</transmission>

<joint name="Revolute_12" type="continuous">
  <origin xyz="0.060355 0.0 0.065755" rpy="0 0 0"/>
  <parent link="l_link_down3"/>
  <child link="v_link2"/>
  <axis xyz="-0.0 -0.707107 -0.707107"/>
</joint>
<transmission name="Revolute_12_tran">
  <type>transmission_interface/SimpleTransmission</type>
  <joint name="Revolute_12">
    <hardwareInterface>PositionJointInterface</hardwareInterface>
  </joint>
  <actuator name="Revolute_12_actr">
    <hardwareInterface>PositionJointInterface</hardwareInterface>
    <mechanicalReduction>1</mechanicalReduction>
  </actuator>
</transmission>

<joint name="Revolute_14" type="continuous">
  <origin xyz="0.0 0.060355 0.065755" rpy="0 0 0"/>
  <parent link="l_link_down4"/>
  <child link="v_link3"/>
  <axis xyz="0.707107 -0.0 -0.707107"/>
</joint>
<transmission name="Revolute_14_tran">
  <type>transmission_interface/SimpleTransmission</type>
  <joint name="Revolute_14">
    <hardwareInterface>PositionJointInterface</hardwareInterface>
  </joint>
  <actuator name="Revolute_14_actr">
    <hardwareInterface>PositionJointInterface</hardwareInterface>
    <mechanicalReduction>1</mechanicalReduction>
  </actuator>
</transmission>

<joint name="Revolute_16" type="continuous">
  <origin xyz="-0.060355 0.0 0.065755" rpy="0 0 0"/>
  <parent link="l_link_down1"/>
  <child link="v_link4"/>
  <axis xyz="0.0 0.707107 -0.707107"/>
</joint>
<transmission name="Revolute_16_tran">
  <type>transmission_interface/SimpleTransmission</type>
  <joint name="Revolute_16">
    <hardwareInterface>PositionJointInterface</hardwareInterface>
  </joint>
  <actuator name="Revolute_16_actr">
    <hardwareInterface>PositionJointInterface</hardwareInterface>
    <mechanicalReduction>1</mechanicalReduction>
  </actuator>
</transmission>

</robot>
