<mujoco model="final_project_simplified">
  <compiler angle="radian" meshdir="meshes/"/>
  <asset>
    <mesh name="base_link" file="base_link.stl" scale="0.001 0.001 0.001"/>
    <mesh name="l_link_down4" file="l_link_down4.stl" scale="0.001 0.001 0.001"/>
    <mesh name="l_link_down1" file="l_link_down1.stl" scale="0.001 0.001 0.001"/>
    <mesh name="l_link_down2" file="l_link_down2.stl" scale="0.001 0.001 0.001"/>
    <mesh name="l_link_down3" file="l_link_down3.stl" scale="0.001 0.001 0.001"/>
    <mesh name="v_link4" file="v_link4.stl" scale="0.001 0.001 0.001"/>
    <mesh name="v_link1" file="v_link1.stl" scale="0.001 0.001 0.001"/>
    <mesh name="v_link2" file="v_link2.stl" scale="0.001 0.001 0.001"/>
    <mesh name="v_link3" file="v_link3.stl" scale="0.001 0.001 0.001"/>
    <mesh name="l_link_up1" file="l_link_up1.stl" scale="0.001 0.001 0.001"/>
    <mesh name="l_link_up2" file="l_link_up2.stl" scale="0.001 0.001 0.001"/>
    <mesh name="l_link_up3" file="l_link_up3.stl" scale="0.001 0.001 0.001"/>
    <mesh name="l_link_up4" file="l_link_up4.stl" scale="0.001 0.001 0.001"/>
    <mesh name="ring1" file="ring1.stl" scale="0.001 0.001 0.001"/>
  </asset>
  <worldbody>
    <body name="base_link">
      <inertial pos="0 0 -0.00104665" quat="0.5 0.5 -0.5 0.5" mass="0.238603" diaginertia="0.000823331 0.00041831 0.00041831"/>
      <geom type="mesh" contype="0" conaffinity="0" group="1" density="0" mesh="base_link"/>
      <geom type="mesh" mesh="base_link"/>
      <body name="l_link_down4" pos="0 -0.060355 0">
        <inertial pos="0.0280169 0.0207331 0.0280169" quat="0.353553 0.146447 -0.853553 0.353553" mass="0.0964305" diaginertia="0.000102991 9.92561e-05 1.02616e-05"/>
        <joint name="Revolute_55" pos="0 0 0" axis="0 1 0"/>
        <geom pos="0 0.060355 0" type="mesh" contype="0" conaffinity="0" group="1" density="0" mesh="l_link_down4"/>
        <geom pos="0 0.060355 0" type="mesh" mesh="l_link_down4"/>
        <body name="v_link3" pos="0 0.060355 -0.065755">
          <inertial pos="0.0491587 0 0.120755" mass="0.02882" diaginertia="2.8657e-06 2.33879e-06 1.49746e-06"/>
          <joint name="Revolute_62" pos="0 0 0" axis="-0.707107 0 -0.707107"/>
          <geom pos="0 0 0.065755" type="mesh" contype="0" conaffinity="0" group="1" density="0" mesh="v_link3"/>
          <geom pos="0 0 0.065755" type="mesh" mesh="v_link3"/>
          <body name="l_link_up2" pos="-0.046779 0 0.128976">
            <inertial pos="0.0747959 0.0396219 0.0187621" quat="0.353553 0.853553 -0.146447 0.353553" mass="0.0964305" diaginertia="0.000102991 9.92561e-05 1.02616e-05"/>
            <joint name="Revolute_68" pos="0 0 0" axis="0.707107 0 -0.707107"/>
            <geom pos="0.046779 0 -0.063221" type="mesh" contype="0" conaffinity="0" group="1" density="0" mesh="l_link_up2"/>
            <geom pos="0.046779 0 -0.063221" type="mesh" mesh="l_link_up2"/>
          </body>
        </body>
      </body>
      <body name="l_link_down1" pos="0.060355 0 0">
        <inertial pos="-0.0207331 0.0280169 0.0280169" quat="0.5 0.5 0.707107 -1.40718e-07" mass="0.0964305" diaginertia="0.000102991 9.92561e-05 1.02616e-05"/>
        <joint name="Revolute_56" pos="0 0 0" axis="-1 0 0"/>
        <geom pos="-0.060355 0 0" type="mesh" contype="0" conaffinity="0" group="1" density="0" mesh="l_link_down1"/>
        <geom pos="-0.060355 0 0" type="mesh" mesh="l_link_down1"/>
        <body name="v_link4" pos="-0.060355 0 -0.065755">
          <inertial pos="0 0.0491587 0.120755" quat="0.707107 0 0 0.707107" mass="0.02882" diaginertia="2.8657e-06 2.33879e-06 1.49746e-06"/>
          <joint name="Revolute_59" pos="0 0 0" axis="0 -0.707107 -0.707107"/>
          <geom pos="0 0 0.065755" type="mesh" contype="0" conaffinity="0" group="1" density="0" mesh="v_link4"/>
          <geom pos="0 0 0.065755" type="mesh" mesh="v_link4"/>
          <body name="l_link_up3" pos="0 -0.046779 0.128976">
            <inertial pos="-0.0396219 0.0747959 0.0187621" quat="-1.41001e-07 0.707107 0.5 0.5" mass="0.0964305" diaginertia="0.000102991 9.92561e-05 1.02616e-05"/>
            <joint name="Revolute_69" pos="0 0 0" axis="0 0.707107 -0.707107"/>
            <geom pos="0 0.046779 -0.063221" type="mesh" contype="0" conaffinity="0" group="1" density="0" mesh="l_link_up3"/>
            <geom pos="0 0.046779 -0.063221" type="mesh" mesh="l_link_up3"/>
          </body>
        </body>
      </body>
      <body name="l_link_down2" pos="0 0.060355 0">
        <inertial pos="-0.0280169 -0.0207331 0.0280169" quat="0.853553 0.353553 -0.353553 0.146447" mass="0.0964305" diaginertia="0.000102991 9.92561e-05 1.02616e-05"/>
        <joint name="Revolute_57" pos="0 0 0" axis="0 -1 0"/>
        <geom pos="0 -0.060355 0" type="mesh" contype="0" conaffinity="0" group="1" density="0" mesh="l_link_down2"/>
        <geom pos="0 -0.060355 0" type="mesh" mesh="l_link_down2"/>
        <body name="v_link1" pos="0 -0.060355 -0.065755">
          <inertial pos="-0.0491587 0 0.120755" mass="0.02882" diaginertia="2.8657e-06 2.33879e-06 1.49746e-06"/>
          <joint name="Revolute_60" pos="0 0 0" axis="0.707107 0 -0.707107"/>
          <geom pos="0 0 0.065755" type="mesh" contype="0" conaffinity="0" group="1" density="0" mesh="v_link1"/>
          <geom pos="0 0 0.065755" type="mesh" mesh="v_link1"/>
          <body name="l_link_up4" pos="0.046779 0 0.128976">
            <inertial pos="-0.0747959 -0.0396219 0.0187621" quat="0.146447 0.353553 -0.353553 0.853553" mass="0.0964305" diaginertia="0.000102991 9.92561e-05 1.02616e-05"/>
            <joint name="Revolute_70" pos="0 0 0" axis="-0.707107 0 -0.707107"/>
            <geom pos="-0.046779 0 -0.063221" type="mesh" contype="0" conaffinity="0" group="1" density="0" mesh="l_link_up4"/>
            <geom pos="-0.046779 0 -0.063221" type="mesh" mesh="l_link_up4"/>
          </body>
        </body>
      </body>
      <body name="l_link_down3" pos="-0.060355 0 0">
        <inertial pos="0.0207331 -0.0280169 0.0280169" quat="0.5 0.5 -1.41001e-07 0.707107" mass="0.0964305" diaginertia="0.000102991 9.92561e-05 1.02616e-05"/>
        <joint name="Revolute_58" pos="0 0 0" axis="1 0 0"/>
        <geom pos="0.060355 0 0" type="mesh" contype="0" conaffinity="0" group="1" density="0" mesh="l_link_down3"/>
        <geom pos="0.060355 0 0" type="mesh" mesh="l_link_down3"/>
        <body name="v_link2" pos="0.060355 0 -0.065755">
          <inertial pos="0 -0.0491587 0.120755" quat="0.707107 0 0 0.707107" mass="0.02882" diaginertia="2.8657e-06 2.33879e-06 1.49746e-06"/>
          <joint name="Revolute_61" pos="0 0 0" axis="0 0.707107 -0.707107"/>
          <geom pos="0 0 0.065755" type="mesh" contype="0" conaffinity="0" group="1" density="0" mesh="v_link2"/>
          <geom pos="0 0 0.065755" type="mesh" mesh="v_link2"/>
          <body name="l_link_up1" pos="0 0.046779 0.128976">
            <inertial pos="0.0396219 -0.0747959 0.0187621" quat="0.707107 -1.40718e-07 0.5 0.5" mass="0.0964305" diaginertia="0.000102991 9.92561e-05 1.02616e-05"/>
            <joint name="Revolute_67" pos="0 0 0" axis="0 -0.707107 -0.707107"/>
            <geom pos="0 -0.046779 -0.063221" type="mesh" contype="0" conaffinity="0" group="1" density="0" mesh="l_link_up1"/>
            <geom pos="0 -0.046779 -0.063221" type="mesh" mesh="l_link_up1"/>
            <body name="ring1" pos="0.060755 -0.124561 0.124561">
              <inertial pos="-0.0598337 0.0800063 -0.0767435" quat="0.587997 0.392808 -0.587879 0.392887" mass="0.248644" diaginertia="0.000857809 0.00045294 0.000418744"/>
              <joint name="Revolute_71" pos="0 0 0" axis="-1 0 0"/>
              <geom pos="-0.060755 0.077782 -0.187782" type="mesh" contype="0" conaffinity="0" group="1" density="0" mesh="ring1"/>
              <geom pos="-0.060755 0.077782 -0.187782" type="mesh" mesh="ring1"/>
            </body>
          </body>
        </body>
      </body>
    </body>
  </worldbody>
</mujoco>
