<?xml version="1.0" ?>
<robot name="parallel_spherical">
<mujoco>
  <compiler balanceinertia="true" discardvisual="false" meshdir="meshes" fusestatic="false"/>
</mujoco>
<link name="base_link">
  <inertial>
    <origin xyz="-0.042083736516522974 -0.07289116885343022 -0.08851433483805454" rpy="0 0 0"/>
    <mass value="0.4147232258009921"/>
    <inertia ixx="0.001528414915038666" iyy="0.0011989241429330019" izz="0.0006744974877580362" ixy="-0.0002853473482560798" iyz="0.0006146183641304883" ixz="0.00035485007365117856"/>
  </inertial>
  <visual>
    <origin xyz="0 0 0" rpy="0 0 0"/>
    <geometry>
      <mesh filename="meshes/base_link.stl" scale="0.001 0.001 0.001"/>
    </geometry>
  </visual>
  <collision>
    <origin xyz="0 0 0" rpy="0 0 0"/>
    <geometry>
      <mesh filename="meshes/base_link.stl" scale="0.001 0.001 0.001"/>
    </geometry>
  </collision>
</link>

<link name="lower_link21">
  <inertial>
    <origin xyz="-0.04077578149701429 0.07062572572270166 0.05763257196504136" rpy="0 0 0"/>
    <mass value="0.38822953270790367"/>
    <inertia ixx="0.0012505082859246824" iyy="0.0009418103508095008" izz="0.0006319183753502812" ixy="0.0002673402668866107" iyz="-0.0005271522035513938" ixz="0.0003043514679006876"/>
  </inertial>
  <visual>
    <origin xyz="-0.0 -0.0 0.1375" rpy="0 0 0"/>
    <geometry>
      <mesh filename="meshes/lower_link21.stl" scale="0.001 0.001 0.001"/>
    </geometry>

  </visual>
  <collision>
    <origin xyz="-0.0 -0.0 0.1375" rpy="0 0 0"/>
    <geometry>
      <mesh filename="meshes/lower_link21.stl" scale="0.001 0.001 0.001"/>
    </geometry>
  </collision>
</link>

<link name="lower_link11">
  <inertial>
    <origin xyz="0.07855246831284729 -4.598011688255099e-17 0.05144741011500657" rpy="0 0 0"/>
    <mass value="0.36173571001560584"/>
    <inertia ixx="0.0005832476015041708" iyy="0.0011529662391312452" izz="0.0005832476015041714" ixy="-1.8491538504083238e-18" iyz="5.713073859433774e-19" ixz="-0.0005103757821198591"/>
  </inertial>
  <visual>
    <origin xyz="-0.0 0.0 0.1225" rpy="0 0 0"/>
    <geometry>
      <mesh filename="meshes/lower_link11.stl" scale="0.001 0.001 0.001"/>
    </geometry>

  </visual>
  <collision>
    <origin xyz="-0.0 0.0 0.1225" rpy="0 0 0"/>
    <geometry>
      <mesh filename="meshes/lower_link11.stl" scale="0.001 0.001 0.001"/>
    </geometry>
  </collision>
</link>

<link name="upper_link11">
  <inertial>
    <origin xyz="-0.04600424980878119 0.06899575539286629 -1.2157214608968236e-07" rpy="0 0 0"/>
    <mass value="0.32011926525348455"/>
    <inertia ixx="0.00040551950032500454" iyy="0.00040551898778093463" izz="0.0007990701408253204" ixy="0.0003512112334040445" iyz="-2.2768245622195593e-18" ixz="-1.3552527156068805e-19"/>
  </inertial>
  <visual>
    <origin xyz="-0.115 0.0 -0.0075" rpy="0 0 0"/>
    <geometry>
      <mesh filename="meshes/upper_link11.stl" scale="0.001 0.001 0.001"/>
    </geometry>

  </visual>
  <collision>
    <origin xyz="-0.115 0.0 -0.0075" rpy="0 0 0"/>
    <geometry>
      <mesh filename="meshes/upper_link11.stl" scale="0.001 0.001 0.001"/>
    </geometry>
  </collision>
</link>

<link name="upper_link21">
  <inertial>
    <origin xyz="-0.03674995201912903 -0.07433880527767278 1.734723475976807e-18" rpy="0 0 0"/>
    <mass value="0.3201192652534845"/>
    <inertia ixx="0.0007096769661393221" iyy="0.00010136152196661653" izz="0.00079907014082532" ixy="-0.0001756058386401146" iyz="1.8295911660692887e-18" ixz="-1.1926223897340549e-18"/>
  </inertial>
  <visual>
    <origin xyz="0.0575 -0.099593 -0.0075" rpy="0 0 0"/>
    <geometry>
      <mesh filename="meshes/upper_link21.stl" scale="0.001 0.001 0.001"/>
    </geometry>

  </visual>
  <collision>
    <origin xyz="0.0575 -0.099593 -0.0075" rpy="0 0 0"/>
    <geometry>
      <mesh filename="meshes/upper_link21.stl" scale="0.001 0.001 0.001"/>
    </geometry>
  </collision>
</link>

<link name="upper_link31">
  <inertial>
    <origin xyz="0.08275420182791021 0.005343049884806175 1.734723475976807e-18" rpy="0 0 0"/>
    <mass value="0.3201192652534845"/>
    <inertia ixx="0.00010136126569458082" iyy="0.0007096772224113549" izz="0.0007990701408253169" ixy="-0.00017560539476393184" iyz="1.870248747537495e-18" ixz="1.212951180468158e-18"/>
  </inertial>
  <visual>
    <origin xyz="0.0575 0.099593 -0.0075" rpy="0 0 0"/>
    <geometry>
      <mesh filename="meshes/upper_link31.stl" scale="0.001 0.001 0.001"/>
    </geometry>

  </visual>
  <collision>
    <origin xyz="0.0575 0.099593 -0.0075" rpy="0 0 0"/>
    <geometry>
      <mesh filename="meshes/upper_link31.stl" scale="0.001 0.001 0.001"/>
    </geometry>
  </collision>
</link>

<link name="ring1">
  <inertial>
    <origin xyz="1.1496595028307575e-15 -0.09999999999999755 -1.2157214656412924e-07" rpy="0 0 0"/>
    <mass value="0.9575334104776773"/>
    <inertia ixx="0.0033571508473524973" iyy="0.0033571508473521" izz="0.006677996643595624" ixy="-8.710230758879053e-17" iyz="5.034795997218266e-17" ixz="-2.5577082162427784e-18"/>
  </inertial>
  <visual>
    <origin xyz="0.0 -0.1 -0.0075" rpy="0 0 0"/>
    <geometry>
      <mesh filename="meshes/ring1.stl" scale="0.001 0.001 0.001"/>
    </geometry>

  </visual>
  <collision>
    <origin xyz="0.0 -0.1 -0.0075" rpy="0 0 0"/>
    <geometry>
      <mesh filename="meshes/ring1.stl" scale="0.001 0.001 0.001"/>
    </geometry>
  </collision>
</link>

<joint name="Revolute_60" type="continuous">
  <origin xyz="0.0 0.0 -0.1375" rpy="0 0 0"/>
  <parent link="base_link"/>
  <child link="lower_link21"/>
  <axis xyz="0.0 0.0 -1.0"/>
</joint>
<transmission name="Revolute_60_tran">
  <type>transmission_interface/SimpleTransmission</type>
  <joint name="Revolute_60">
    <hardwareInterface>PositionJointInterface</hardwareInterface>
  </joint>
  <actuator name="Revolute_60_actr">
    <hardwareInterface>PositionJointInterface</hardwareInterface>
    <mechanicalReduction>1</mechanicalReduction>
  </actuator>
</transmission>

<joint name="Revolute_61" type="continuous">
  <origin xyz="0.0 -0.0 0.015" rpy="0 0 0"/>
  <parent link="lower_link21"/>
  <child link="lower_link11"/>
  <axis xyz="0.0 0.0 -1.0"/>
</joint>
<transmission name="Revolute_61_tran">
  <type>transmission_interface/SimpleTransmission</type>
  <joint name="Revolute_61">
    <hardwareInterface>PositionJointInterface</hardwareInterface>
  </joint>
  <actuator name="Revolute_61_actr">
    <hardwareInterface>PositionJointInterface</hardwareInterface>
    <mechanicalReduction>1</mechanicalReduction>
  </actuator>
</transmission>

<joint name="Revolute_62" type="continuous">
  <origin xyz="0.115 0.0 0.13" rpy="0 0 0"/>
  <parent link="lower_link11"/>
  <child link="upper_link11"/>
  <axis xyz="1.0 0.0 0.0"/>
</joint>
<transmission name="Revolute_62_tran">
  <type>transmission_interface/SimpleTransmission</type>
  <joint name="Revolute_62">
    <hardwareInterface>PositionJointInterface</hardwareInterface>
  </joint>
  <actuator name="Revolute_62_actr">
    <hardwareInterface>PositionJointInterface</hardwareInterface>
    <mechanicalReduction>1</mechanicalReduction>
  </actuator>
</transmission>

<joint name="Revolute_63" type="continuous">
  <origin xyz="-0.0575 0.099593 0.145" rpy="0 0 0"/>
  <parent link="lower_link21"/>
  <child link="upper_link21"/>
  <axis xyz="-0.5 0.866025 -0.0"/>
</joint>
<transmission name="Revolute_63_tran">
  <type>transmission_interface/SimpleTransmission</type>
  <joint name="Revolute_63">
    <hardwareInterface>PositionJointInterface</hardwareInterface>
  </joint>
  <actuator name="Revolute_63_actr">
    <hardwareInterface>PositionJointInterface</hardwareInterface>
    <mechanicalReduction>1</mechanicalReduction>
  </actuator>
</transmission>

<joint name="Revolute_64" type="continuous">
  <origin xyz="-0.0575 -0.099593 0.0075" rpy="0 0 0"/>
  <parent link="base_link"/>
  <child link="upper_link31"/>
  <axis xyz="-0.5 -0.866025 0.0"/>
</joint>
<transmission name="Revolute_64_tran">
  <type>transmission_interface/SimpleTransmission</type>
  <joint name="Revolute_64">
    <hardwareInterface>PositionJointInterface</hardwareInterface>
  </joint>
  <actuator name="Revolute_64_actr">
    <hardwareInterface>PositionJointInterface</hardwareInterface>
    <mechanicalReduction>1</mechanicalReduction>
  </actuator>
</transmission>

<joint name="Revolute_68" type="continuous">
  <origin xyz="-0.115 0.1 0.0" rpy="0 0 0"/>
  <parent link="upper_link11"/>
  <child link="ring1"/>
  <axis xyz="0.0 1.0 -0.0"/>
</joint>
<transmission name="Revolute_68_tran">
  <type>transmission_interface/SimpleTransmission</type>
  <joint name="Revolute_68">
    <hardwareInterface>PositionJointInterface</hardwareInterface>
  </joint>
  <actuator name="Revolute_68_actr">
    <hardwareInterface>PositionJointInterface</hardwareInterface>
    <mechanicalReduction>1</mechanicalReduction>
  </actuator>
</transmission>

</robot>
