<mujoco model="3-joint-planar-manipulator">

    <actuator>
        <motor gear="1000" joint="hinge_1" name="motor_1" ctrlrange="-1 1" ctrllimited="true"/>
        <motor gear="1000" joint="hinge_2" name="motor_2" ctrlrange="-1 1" ctrllimited="true"/>
        <motor gear="1000" joint="hinge_3" name="motor_3" ctrlrange="-1 1" ctrllimited="true"/>
    </actuator>

    <worldbody>
        <light pos="0 0 1"/>
        <body name="link_1" pos="0 0 0" euler="90 0 0">
            <joint name="hinge_1" axis="0 0 1"/>
            <geom type="box" size=".5 .1 .1" pos="0.5 0 0" rgba=".9 .7 .1 1"/>
            <geom type="cylinder" size=".2 .2" rgba=".3 .9 .3 .4"/>
            <body name="link_2" pos="1 0 0">
                <joint name="hinge_2" axis="0 0 1"/>
                <geom type="box" size=".5 .1 .1" pos="0.5 0 0" rgba=".9 .7 .1 1"/>
                <geom type="cylinder" size=".2 .2" rgba=".3 .9 .3 .4"/>
                <body name="link_3" pos="1 0 0">
                    <joint name="hinge_3" axis="0 0 1"/>
                    <geom type="box" size=".5 .1 .1" pos="0.5 0 0" rgba=".9 .7 .1 1"/>
                    <geom type="cylinder" size=".2 .2" rgba=".3 .9 .3 .4"/>
                    <body name="end_effector" pos="1 0 0">
                        <geom type="sphere" size=".25" mass="0.05"/>
                    </body>
                </body>
            </body>
        </body>
    </worldbody>

    <contact>
        <exclude body1="link_1" body2="link_2"/>
        <exclude body1="link_1" body2="link_3"/>
        <exclude body1="link_1" body2="end_effector"/>
        <exclude body1="link_2" body2="link_3"/>
        <exclude body1="link_2" body2="end_effector"/>
        <exclude body1="link_3" body2="end_effector"/>
    </contact>
 
</mujoco>