<?xml version="1.0" ?>
<robot name="parallel_spherical">
<mujoco>
  <compiler balanceinertia="true" discardvisual="false" meshdir="meshes" fusestatic="false"/>
</mujoco>
<link name="base_link">
  <inertial>
    <origin xyz="1.1370661670351178e-15 2.6096600554904347e-15 0.007499999999999476" rpy="0 0 0"/>
    <mass value="0.9575334104776773"/>
    <inertia ixx="0.0033571508473524973" iyy="0.0033571508473521" izz="0.006677996643595624" ixy="-8.710230758879048e-17" iyz="4.756714133691144e-17" ixz="2.2311041902809987e-19"/>
  </inertial>
  <visual>
    <origin xyz="0 0 0" rpy="0 0 0"/>
    <geometry>
      <mesh filename="meshes/base_link.stl" scale="0.001 0.001 0.001"/>
    </geometry>

  </visual>
  <collision>
    <origin xyz="0 0 0" rpy="0 0 0"/>
    <geometry>
      <mesh filename="meshes/base_link.stl" scale="0.001 0.001 0.001"/>
    </geometry>
  </collision>
</link>

<link name="lower_link21">
  <inertial>
    <origin xyz="0.016724251686422664 -0.028967301091258432 -0.08736741279252863" rpy="0 0 0"/>
    <mass value="0.3882295327079039"/>
    <inertia ixx="0.0012505076433464192" iyy="0.000941810438615773" izz="0.0006319189301222778" ixy="0.0002673407980274113" iyz="-0.0005271518955243472" ixz="0.00030435214317984735"/>
  </inertial>
  <visual>
    <origin xyz="0.0575 -0.099593 -0.0075" rpy="0 0 0"/>
    <geometry>
      <mesh filename="meshes/lower_link21.stl" scale="0.001 0.001 0.001"/>
    </geometry>

  </visual>
  <collision>
    <origin xyz="0.0575 -0.099593 -0.0075" rpy="0 0 0"/>
    <geometry>
      <mesh filename="meshes/lower_link21.stl" scale="0.001 0.001 0.001"/>
    </geometry>
  </collision>
</link>

<link name="lower_link31">
  <inertial>
    <origin xyz="0.015416315326828862 0.026701820321948358 -0.09601432952433928" rpy="0 0 0"/>
    <mass value="0.4147232258009921"/>
    <inertia ixx="0.0015284149682778447" iyy="0.0011989238450718078" izz="0.0006744977323800533" ixy="-0.0002853473881346679" iyz="0.0006146185126120543" ixz="0.0003548499404496693"/>
  </inertial>
  <visual>
    <origin xyz="0.0575 0.099593 -0.0075" rpy="0 0 0"/>
    <geometry>
      <mesh filename="meshes/lower_link31.stl" scale="0.001 0.001 0.001"/>
    </geometry>
  </visual>
  <collision>
    <origin xyz="0.0575 0.099593 -0.0075" rpy="0 0 0"/>
    <geometry>
      <mesh filename="meshes/lower_link31.stl" scale="0.001 0.001 0.001"/>
    </geometry>
  </collision>
</link>

<link name="lower_link11">
  <inertial>
    <origin xyz="-0.03644748444172061 1.2925501269289129e-08 -0.07855249023412866" rpy="0 0 0"/>
    <mass value="0.36173571001560584"/>
    <inertia ixx="0.0005832482154357636" iyy="0.0011529662391309634" izz="0.0005832469875728615" ixy="-3.5900558129703873e-10" iyz="-4.0074867189899194e-10" ixz="-0.0005103757821193632"/>
  </inertial>
  <visual>
    <origin xyz="-0.115 -0.0 -0.0075" rpy="0 0 0"/>
    <geometry>
      <mesh filename="meshes/lower_link11.stl" scale="0.001 0.001 0.001"/>
    </geometry>

  </visual>
  <collision>
    <origin xyz="-0.115 -0.0 -0.0075" rpy="0 0 0"/>
    <geometry>
      <mesh filename="meshes/lower_link11.stl" scale="0.001 0.001 0.001"/>
    </geometry>
  </collision>
</link>

<link name="upper_link31">
  <inertial>
    <origin xyz="-0.06134873912607851 -0.044249984205424336 1.734723475976807e-18" rpy="0 0 0"/>
    <mass value="0.3201192652534845"/>
    <inertia ixx="0.00010136126569458082" iyy="0.000709677222411355" izz="0.0007990701408253169" ixy="-0.00017560539476393195" iyz="1.8431436932253575e-18" ixz="1.212951180468158e-18"/>
  </inertial>
  <visual>
    <origin xyz="-0.086603 0.05 -0.0075" rpy="0 0 0"/>
    <geometry>
      <mesh filename="meshes/upper_link31.stl" scale="0.001 0.001 0.001"/>
    </geometry>

  </visual>
  <collision>
    <origin xyz="-0.086603 0.05 -0.0075" rpy="0 0 0"/>
    <geometry>
      <mesh filename="meshes/upper_link31.stl" scale="0.001 0.001 0.001"/>
    </geometry>
  </collision>
</link>

<link name="upper_link11">
  <inertial>
    <origin xyz="0.06899575019121883 -0.031004176426672525 1.734723475976807e-18" rpy="0 0 0"/>
    <mass value="0.32011926525348455"/>
    <inertia ixx="0.00040551950032500454" iyy="0.00040551898778093485" izz="0.00079907014082532" ixy="0.0003512112334040447" iyz="-2.2497195079074217e-18" ixz="-2.710505431213761e-20"/>
  </inertial>
  <visual>
    <origin xyz="0.0 -0.1 -0.0075" rpy="0 0 0"/>
    <geometry>
      <mesh filename="meshes/upper_link11.stl" scale="0.001 0.001 0.001"/>
    </geometry>

  </visual>
  <collision>
    <origin xyz="0.0 -0.1 -0.0075" rpy="0 0 0"/>
    <geometry>
      <mesh filename="meshes/upper_link11.stl" scale="0.001 0.001 0.001"/>
    </geometry>
  </collision>
</link>

<link name="upper_link21">
  <inertial>
    <origin xyz="-0.0076470110651403606 0.07525416063209672 2.6020852139652106e-18" rpy="0 0 0"/>
    <mass value="0.3201192652534844"/>
    <inertia ixx="0.0007096769661393216" iyy="0.00010136152196661566" izz="0.0007990701408253187" ixy="-0.00017560583864011515" iyz="2.0057740190981832e-18" ixz="-1.2468324983583301e-18"/>
  </inertial>
  <visual>
    <origin xyz="0.086603 0.05 -0.0075" rpy="0 0 0"/>
    <geometry>
      <mesh filename="meshes/upper_link21.stl" scale="0.001 0.001 0.001"/>
    </geometry>

  </visual>
  <collision>
    <origin xyz="0.086603 0.05 -0.0075" rpy="0 0 0"/>
    <geometry>
      <mesh filename="meshes/upper_link21.stl" scale="0.001 0.001 0.001"/>
    </geometry>
  </collision>
</link>

<joint name="Revolute_1" type="continuous">
  <origin xyz="0.029103 0.149593 0.0" rpy="0 0 0"/>
  <parent link="upper_link21"/>
  <child link="lower_link21"/>
  <axis xyz="0.5 -0.866025 0.0"/>
</joint>
<transmission name="Revolute_1_tran">
  <type>transmission_interface/SimpleTransmission</type>
  <joint name="Revolute_1">
    <hardwareInterface>PositionJointInterface</hardwareInterface>
  </joint>
  <actuator name="Revolute_1_actr">
    <hardwareInterface>PositionJointInterface</hardwareInterface>
    <mechanicalReduction>1</mechanicalReduction>
  </actuator>
</transmission>

<joint name="Revolute_2" type="continuous">
  <origin xyz="-0.086603 0.05 -0.145" rpy="0 0 0"/>
  <parent link="upper_link31"/>
  <child link="lower_link31"/>
  <axis xyz="0.5 0.866025 0.0"/>
</joint>
<transmission name="Revolute_2_tran">
  <type>transmission_interface/SimpleTransmission</type>
  <joint name="Revolute_2">
    <hardwareInterface>PositionJointInterface</hardwareInterface>
  </joint>
  <actuator name="Revolute_2_actr">
    <hardwareInterface>PositionJointInterface</hardwareInterface>
    <mechanicalReduction>1</mechanicalReduction>
  </actuator>
</transmission>

<joint name="Revolute_3" type="continuous">
  <origin xyz="0.0 -0.1 -0.13" rpy="0 0 0"/>
  <parent link="upper_link11"/>
  <child link="lower_link11"/>
  <axis xyz="-1.0 0.0 0.0"/>
</joint>
<transmission name="Revolute_3_tran">
  <type>transmission_interface/SimpleTransmission</type>
  <joint name="Revolute_3">
    <hardwareInterface>PositionJointInterface</hardwareInterface>
  </joint>
  <actuator name="Revolute_3_actr">
    <hardwareInterface>PositionJointInterface</hardwareInterface>
    <mechanicalReduction>1</mechanicalReduction>
  </actuator>
</transmission>

<joint name="Revolute_4" type="continuous">
  <origin xyz="0.086603 -0.05 0.0075" rpy="0 0 0"/>
  <parent link="base_link"/>
  <child link="upper_link31"/>
  <axis xyz="-0.866025 0.5 0.0"/>
</joint>
<transmission name="Revolute_4_tran">
  <type>transmission_interface/SimpleTransmission</type>
  <joint name="Revolute_4">
    <hardwareInterface>PositionJointInterface</hardwareInterface>
  </joint>
  <actuator name="Revolute_4_actr">
    <hardwareInterface>PositionJointInterface</hardwareInterface>
    <mechanicalReduction>1</mechanicalReduction>
  </actuator>
</transmission>

<joint name="Revolute_5" type="continuous">
  <origin xyz="0.0 0.1 0.0075" rpy="0 0 0"/>
  <parent link="base_link"/>
  <child link="upper_link11"/>
  <axis xyz="-0.0 -1.0 0.0"/>
</joint>
<transmission name="Revolute_5_tran">
  <type>transmission_interface/SimpleTransmission</type>
  <joint name="Revolute_5">
    <hardwareInterface>PositionJointInterface</hardwareInterface>
  </joint>
  <actuator name="Revolute_5_actr">
    <hardwareInterface>PositionJointInterface</hardwareInterface>
    <mechanicalReduction>1</mechanicalReduction>
  </actuator>
</transmission>

<joint name="Revolute_6" type="continuous">
  <origin xyz="-0.086603 -0.05 0.0075" rpy="0 0 0"/>
  <parent link="base_link"/>
  <child link="upper_link21"/>
  <axis xyz="0.866025 0.5 0.0"/>
</joint>
<transmission name="Revolute_6_tran">
  <type>transmission_interface/SimpleTransmission</type>
  <joint name="Revolute_6">
    <hardwareInterface>PositionJointInterface</hardwareInterface>
  </joint>
  <actuator name="Revolute_6_actr">
    <hardwareInterface>PositionJointInterface</hardwareInterface>
    <mechanicalReduction>1</mechanicalReduction>
  </actuator>
</transmission>

<!-- <joint name="Revolute_7" type="continuous">
  <origin xyz="0.0575 -0.099593 -0.13" rpy="0 0 0"/>
  <parent link="lower_link21"/>
  <child link="lower_link11"/>
  <axis xyz="1e-06 0.0 -1.0"/>
</joint>
<transmission name="Revolute_7_tran">
  <type>transmission_interface/SimpleTransmission</type>
  <joint name="Revolute_7">
    <hardwareInterface>PositionJointInterface</hardwareInterface>
  </joint>
  <actuator name="Revolute_7_actr">
    <hardwareInterface>PositionJointInterface</hardwareInterface>
    <mechanicalReduction>1</mechanicalReduction>
  </actuator>
</transmission> -->

<!-- <joint name="Revolute_8" type="continuous">
  <origin xyz="0.0575 -0.099593 -0.145" rpy="0 0 0"/>
  <parent link="lower_link21"/>
  <child link="lower_link31"/>
  <axis xyz="-1e-06 -1e-06 1.0"/>
</joint>
<transmission name="Revolute_8_tran">
  <type>transmission_interface/SimpleTransmission</type>
  <joint name="Revolute_8">
    <hardwareInterface>PositionJointInterface</hardwareInterface>
  </joint>
  <actuator name="Revolute_8_actr">
    <hardwareInterface>PositionJointInterface</hardwareInterface>
    <mechanicalReduction>1</mechanicalReduction>
  </actuator>
</transmission> -->

</robot>
